<?xml version="1.0"?>
<!-- Minimal generated SDF -->
<sdf version="1.6">
  <model name="brick_with_texture_1dof">
    <link name="brick_base_link">
    </link>
    <link name='brick_link'>
    <inertial>
      <pose>0 0 0 0 0 0</pose>
      <mass>0.028</mass>
      <inertia>
        <ixx>1.17e-5</ixx>
        <ixy>0</ixy>
        <ixz>0</ixz>
        <iyy>1.9e-5</iyy>
        <iyz>0</iyz>
        <izz>1.9e-5</izz>
      </inertia>
    </inertial>

      <visual name='brick_with_texture'>
        <pose>0 0 0 0 1.57 0</pose>
          <geometry>
            <mesh>
              <uri>./meshes/simple_brick.obj</uri>
              <scale>1.0 1.0 1.0</scale>
            </mesh>
          </geometry>
          <material>
            <drake:diffuse_map>./textures/simple_brick_color.png</drake:diffuse_map>
            <drake:roughness_map>./textures/simple_brick_roughness.png</drake:roughness_map>
            <drake:metalness_map>./textures/simple_brick_metalness.png</drake:metalness_map>
          </material>
      </visual>

      <collision name="box_collision">
        <pose>0.0 0.0 0.0 0.0 0.0 0.0</pose>
        <geometry>
          <box>
            <size>0.1 0.1 0.07</size>
          </box>
        </geometry>
      </collision>
    <collision name='sphere1_collision'>
      <pose>-0.035 0.05 0.05 0 0 0</pose>
      <geometry>
        <sphere>
<!--          TODO(rcory) I'm sure this affects that master sim too-->
          <radius>.0003</radius>
        </sphere>
      </geometry>
    </collision>
    <collision name='sphere2_collision'>
      <pose>-0.035 -0.05 0.05 0 0 0</pose>
      <geometry>
        <sphere>
          <radius>.0003</radius>
        </sphere>
      </geometry>
    </collision>
    <collision name='sphere3_collision'>
      <pose>-0.035 0.05 -0.05 0 0 0</pose>
      <geometry>
        <sphere>
          <radius>.0003</radius>
        </sphere>
      </geometry>
    </collision>
    <collision name='sphere4_collision'>
      <pose>-0.035 -0.05 -0.05 0 0 0</pose>
      <geometry>
        <sphere>
          <radius>.0003</radius>
        </sphere>
      </geometry>
    </collision>
    </link>
   <joint name="brick_revolute_x_joint" type="revolute">
     <parent>brick_base_link</parent>
     <child>brick_link</child>
     <axis>
       <xyz> 1 0 0 </xyz>
       <limit>
         <!-- Drake parses a zero effort joint as an un-actuated joint. -->
         <effort> 0 </effort>
       </limit>
       <dynamics>
         <damping>.0008</damping>
       </dynamics>
       <use_parent_model_frame>1</use_parent_model_frame>
     </axis>
   </joint>
  </model>
</sdf>
